Workbook

Sheet Data
B1: No | C1: Age | D1: Age Category | E1: Gender | F1: GenderCategory | G1: Body weight | H1: body height | I1: BMI | J1: Obesity category | K1: BMI category | L1: Hypertension | M1: DM type 2 | N1: Hand grip test | O1: HGT Category | P1: HGT Cat No | Q1: Gait speed | R1: gait speed category | S1: gait speed cat no | T1: BIA | U1: BIA Category | V1: BIA Cat no | W1: Sarcopenia cat | X1: Sarcopenia | Y1: HOMA IR | Z1: Tertil HOMA-IR
B2: 1 | C2: 32 | D2: 1 | E2: female | F2: =IF(E2="Male",1,2) -> 2 | G2: 72.5 | H2: 157 | I2: =SUM(G2/((H2/100)*(H2/100))) -> 29.412958 | J2: Grade 1 Obesity | K2: 2 | L2: No | M2: No | N2: 27.5 | O2: =IF(N2>18,"Normal","Abnormal") -> Normal | P2: 1 | Q2: 1.1 | R2: Normal | S2: 1 | T2: 5.6 | U2: Normal | V2: 1 | W2: Normal | X2: 1 | Y2: 1.3 | Z2: =IF(Data!Y2<2.1,"Tertil 1",IF(Data!Y2<=2.6,"Tertil 2","Tertil 3")) -> Tertil 1
B3: 2 | C3: 35 | D3: 1 | E3: Male | F3: =IF(E3="Male",1,2) -> 1 | G3: 135 | H3: 180 | I3: =SUM(G3/((H3/100)*(H3/100))) -> 41.666667 | J3: Grade 2 Obesity | K3: 3 | L3: No | M3: No | N3: 39.2 | O3: =IF(N3>28,"Normal","Abnormal") -> Normal | P3: 1 | Q3: 1 | R3: Normal | S3: 1 | T3: 7.2 | U3: Normal | V3: 1 | W3: Normal | X3: 1 | Y3: 5.3 | Z3: =IF(Data!Y3<2.1,"Tertil 1",IF(Data!Y3<=2.6,"Tertil 2","Tertil 3")) -> Tertil 3
B4: 3 | C4: 30 | D4: 1 | E4: Male | F4: =IF(E4="Male",1,2) -> 1 | G4: 123.8 | H4: 173 | I4: =SUM(G4/((H4/100)*(H4/100))) -> 41.364563 | J4: Grade 2 Obesity | K4: 3 | L4: No | M4: No | N4: 43 | O4: =IF(N4>28,"Normal","Abnormal") -> Normal | P4: 1 | Q4: 1 | R4: Normal | S4: 1 | T4: 7.3 | U4: Normal | V4: 1 | W4: Normal | X4: 1 | Y4: 3.6 | Z4: =IF(Data!Y4<2.1,"Tertil 1",IF(Data!Y4<=2.6,"Tertil 2","Tertil 3")) -> Tertil 3
B5: 4 | C5: 34 | D5: 1 | E5: female | F5: =IF(E5="Male",1,2) -> 2 | G5: 97.4 | H5: 165 | I5: =SUM(G5/((H5/100)*(H5/100))) -> 35.775941 | J5: Grade 2 Obesity | K5: 3 | L5: No | M5: No | N5: 27.4 | O5: =IF(N5>18,"Normal","Abnormal") -> Normal | P5: 1 | Q5: 1.1 | R5: Normal | S5: 1 | T5: 4 | U5: Abnormal | V5: 2 | W5: sarcpenia | X5: 2 | Y5: 1.2 | Z5: =IF(Data!Y5<2.1,"Tertil 1",IF(Data!Y5<=2.6,"Tertil 2","Tertil 3")) -> Tertil 1
B6: 5 | C6: 28 | D6: 1 | E6: female | F6: =IF(E6="Male",1,2) -> 2 | G6: 76.6 | H6: 150 | I6: =SUM(G6/((H6/100)*(H6/100))) -> 34.044444 | J6: Grade 2 Obesity | K6: 3 | L6: No | M6: No | N6: 23.9 | O6: =IF(N6>18,"Normal","Abnormal") -> Normal | P6: 1 | Q6: 1.2 | R6: Normal | S6: 1 | T6: 5.5 | U6: Abnormal | V6: 2 | W6: sarcpenia | X6: 2 | Y6: 2.1 | Z6: =IF(Data!Y6<2.1,"Tertil 1",IF(Data!Y6<=2.6,"Tertil 2","Tertil 3")) -> Tertil 2
B7: 6 | C7: 31 | D7: 1 | E7: female | F7: =IF(E7="Male",1,2) -> 2 | G7: 71.8 | H7: 148 | I7: =SUM(G7/((H7/100)*(H7/100))) -> 32.779401 | J7: Grade 2 Obesity | K7: 3 | L7: No | M7: No | N7: 24.7 | O7: =IF(N7>18,"Normal","Abnormal") -> Normal | P7: 1 | Q7: 1.3 | R7: Normal | S7: 1 | T7: 6 | U7: Normal | V7: 1 | W7: Normal | X7: 1 | Y7: 1.4 | Z7: =IF(Data!Y7<2.1,"Tertil 1",IF(Data!Y7<=2.6,"Tertil 2","Tertil 3")) -> Tertil 1
B8: 7 | C8: 37 | D8: 1 | E8: Male | F8: =IF(E8="Male",1,2) -> 1 | G8: 103.6 | H8: 172 | I8: =SUM(G8/((H8/100)*(H8/100))) -> 35.018929 | J8: Grade 2 Obesity | K8: 3 | L8: No | M8: No | N8: 46 | O8: =IF(N8>28,"Normal","Abnormal") -> Normal | P8: 1 | Q8: 1 | R8: Normal | S8: 1 | T8: 7.7 | U8: Normal | V8: 1 | W8: Normal | X8: 1 | Y8: 2.4 | Z8: =IF(Data!Y8<2.1,"Tertil 1",IF(Data!Y8<=2.6,"Tertil 2","Tertil 3")) -> Tertil 2
B9: 8 | C9: 34 | D9: 1 | E9: female | F9: =IF(E9="Male",1,2) -> 2 | G9: 133.2 | H9: 156 | I9: =SUM(G9/((H9/100)*(H9/100))) -> 54.733728 | J9: Grade 2 Obesity | K9: 3 | L9: No | M9: No | N9: 20.7 | O9: =IF(N9>18,"Normal","Abnormal") -> Normal | P9: 1 | Q9: 1 | R9: Normal | S9: 1 | T9: 3.2 | U9: Abnormal | V9: 2 | W9: sarcpenia | X9: 2 | Y9: 3.9 | Z9: =IF(Data!Y9<2.1,"Tertil 1",IF(Data!Y9<=2.6,"Tertil 2","Tertil 3")) -> Tertil 3
B10: 9 | C10: 30 | D10: 1 | E10: Male | F10: =IF(E10="Male",1,2) -> 1 | G10: 122.6 | H10: 167 | I10: =SUM(G10/((H10/100)*(H10/100))) -> 43.959984 | J10: Grade 2 Obesity | K10: 3 | L10: No | M10: No | N10: 57.5 | O10: =IF(N10>28,"Normal","Abnormal") -> Normal | P10: 1 | Q10: 1 | R10: Normal | S10: 1 | T10: 6.27 | U10: =IF(T10>7,"Normal","Abnormal") -> Abnormal | V10: 2 | W10: sarcpenia | X10: 2 | Y10: 1.4 | Z10: =IF(Data!Y10<2.1,"Tertil 1",IF(Data!Y10<=2.6,"Tertil 2","Tertil 3")) -> Tertil 1
B11: 10 | C11: 31 | D11: 1 | E11: female | F11: =IF(E11="Male",1,2) -> 2 | G11: 79.9 | H11: 150 | I11: =SUM(G11/((H11/100)*(H11/100))) -> 35.511111 | J11: Grade 2 Obesity | K11: 3 | L11: No | M11: No | N11: 24.9 | O11: =IF(N11>18,"Normal","Abnormal") -> Normal | P11: 1 | Q11: 1.2 | R11: Normal | S11: 1 | T11: 4.96 | U11: =IF(T11>5.7,"Normal","Abnormal") -> Abnormal | V11: 2 | W11: sarcpenia | X11: 2 | Y11: 1.9 | Z11: =IF(Data!Y11<2.1,"Tertil 1",IF(Data!Y11<=2.6,"Tertil 2","Tertil 3")) -> Tertil 1
B12: 11 | C12: 29 | D12: 1 | E12: female | F12: =IF(E12="Male",1,2) -> 2 | G12: 98.6 | H12: 164 | I12: =SUM(G12/((H12/100)*(H12/100))) -> 36.659726 | J12: Grade 2 Obesity | K12: 3 | L12: No | M12: No | N12: 22 | O12: =IF(N12>18,"Normal","Abnormal") -> Normal | P12: 1 | Q12: 1.1 | R12: =IF(Q12<1,"Abnormal","Normal") -> Normal | S12: 1 | T12: 3.7 | U12: =IF(T12>5.7,"Normal","Abnormal") -> Abnormal | V12: 2 | W12: sarcpenia | X12: 2 | Y12: 8.5 | Z12: =IF(Data!Y12<2.1,"Tertil 1",IF(Data!Y12<=2.6,"Tertil 2","Tertil 3")) -> Tertil 3
B13: 12 | C13: 31 | D13: 1 | E13: Male | F13: =IF(E13="Male",1,2) -> 1 | G13: 82.1 | H13: 163 | I13: =SUM(G13/((H13/100)*(H13/100))) -> 30.900674 | J13: Grade 2 Obesity | K13: 3 | L13: No | M13: No | N13: 42 | O13: =IF(N13>28,"Normal","Abnormal") -> Normal | P13: 1 | Q13: 1.3 | R13: =IF(Q13<1,"Abnormal","Normal") -> Normal | S13: 1 | T13: 8.31 | U13: =IF(T13>7,"Normal","Abnormal") -> Normal | V13: 1 | W13: Normal | X13: 1 | Y13: 20.6 | Z13: =IF(Data!Y13<2.1,"Tertil 1",IF(Data!Y13<=2.6,"Tertil 2","Tertil 3")) -> Tertil 3
B14: 13 | C14: 36 | D14: 1 | E14: female | F14: =IF(E14="Male",1,2) -> 2 | G14: 68.7 | H14: 153 | I14: =SUM(G14/((H14/100)*(H14/100))) -> 29.347687 | J14: Grade 1 Obesity | K14: 2 | L14: No | M14: No | N14: 28 | O14: =IF(N14>18,"Normal","Abnormal") -> Normal | P14: 1 | Q14: 1.1 | R14: =IF(Q14<1,"Abnormal","Normal") -> Normal | S14: 1 | T14: 6.41 | U14: =IF(T14>5.7,"Normal","Abnormal") -> Normal | V14: 1 | W14: Normal | X14: 1 | Y14: 1.4 | Z14: =IF(Data!Y14<2.1,"Tertil 1",IF(Data!Y14<=2.6,"Tertil 2","Tertil 3")) -> Tertil 1
B15: 14 | C15: 29 | D15: 1 | E15: Male | F15: =IF(E15="Male",1,2) -> 1 | G15: 78.6 | H15: 162 | I15: =SUM(G15/((H15/100)*(H15/100))) -> 29.949703 | J15: Grade 1 Obesity | K15: 2 | L15: No | M15: No | N15: 32.8 | O15: =IF(N15>28,"Normal","Abnormal") -> Normal | P15: 1 | Q15: 1.2 | R15: =IF(Q15<1,"Abnormal","Normal") -> Normal | S15: 1 | T15: 8.37 | U15: =IF(T15>7,"Normal","Abnormal") -> Normal | V15: 1 | W15: Normal | X15: 1 | Y15: 5.3 | Z15: =IF(Data!Y15<2.1,"Tertil 1",IF(Data!Y15<=2.6,"Tertil 2","Tertil 3")) -> Tertil 3
B16: 15 | C16: 28 | D16: 1 | E16: Male | F16: =IF(E16="Male",1,2) -> 1 | G16: 96.7 | H16: 168 | I16: =SUM(G16/((H16/100)*(H16/100))) -> 34.261621 | J16: Grade 2 Obesity | K16: 3 | L16: No | M16: No | N16: 37 | O16: =IF(N16>28,"Normal","Abnormal") -> Normal | P16: 1 | Q16: 1.2 | R16: =IF(Q16<1,"Abnormal","Normal") -> Normal | S16: 1 | T16: 4.5 | U16: =IF(T16>7,"Normal","Abnormal") -> Abnormal | V16: 2 | W16: sarcpenia | X16: 2 | Y16: 2.9 | Z16: =IF(Data!Y16<2.1,"Tertil 1",IF(Data!Y16<=2.6,"Tertil 2","Tertil 3")) -> Tertil 3
B17: 16 | C17: 27 | D17: 1 | E17: Male | F17: =IF(E17="Male",1,2) -> 1 | G17: 105.8 | H17: 174 | I17: =SUM(G17/((H17/100)*(H17/100))) -> 34.945171 | J17: Grade 2 Obesity | K17: 3 | L17: No | M17: No | N17: 40.2 | O17: =IF(N17>28,"Normal","Abnormal") -> Normal | P17: 1 | Q17: 1.1 | R17: =IF(Q17<1,"Abnormal","Normal") -> Normal | S17: 1 | T17: 7.84 | U17: =IF(T17>7,"Normal","Abnormal") -> Normal | V17: 1 | W17: Normal | X17: 1 | Y17: 2.8 | Z17: =IF(Data!Y17<2.1,"Tertil 1",IF(Data!Y17<=2.6,"Tertil 2","Tertil 3")) -> Tertil 3
B18: 17 | C18: 31 | D18: 1 | E18: Male | F18: =IF(E18="Male",1,2) -> 1 | G18: 105 | H18: 175 | I18: =SUM(G18/((H18/100)*(H18/100))) -> 34.285714 | J18: Grade 2 Obesity | K18: 3 | L18: No | M18: No | N18: 42 | O18: =IF(N18>28,"Normal","Abnormal") -> Normal | P18: 1 | Q18: 1 | R18: =IF(Q18<1,"Abnormal","Normal") -> Normal | S18: 1 | T18: 7.05 | U18: =IF(T18>7,"Normal","Abnormal") -> Normal | V18: 1 | W18: Normal | X18: 1 | Y18: 1.5 | Z18: =IF(Data!Y18<2.1,"Tertil 1",IF(Data!Y18<=2.6,"Tertil 2","Tertil 3")) -> Tertil 1
B19: 18 | C19: 34 | D19: 1 | E19: female | F19: =IF(E19="Male",1,2) -> 2 | G19: 71.6 | H19: 150 | I19: =SUM(G19/((H19/100)*(H19/100))) -> 31.822222 | J19: Grade 2 Obesity | K19: 3 | L19: No | M19: No | N19: 28 | O19: =IF(N19>18,"Normal","Abnormal") -> Normal | P19: 1 | Q19: 1 | R19: =IF(Q19<1,"Abnormal","Normal") -> Normal | S19: 1 | T19: 7.73 | U19: =IF(T19>5.7,"Normal","Abnormal") -> Normal | V19: 1 | W19: Normal | X19: 1 | Y19: 1.9 | Z19: =IF(Data!Y19<2.1,"Tertil 1",IF(Data!Y19<=2.6,"Tertil 2","Tertil 3")) -> Tertil 1
B20: 19 | C20: 37 | D20: 1 | E20: female | F20: =IF(E20="Male",1,2) -> 2 | G20: 80.5 | H20: 165 | I20: =SUM(G20/((H20/100)*(H20/100))) -> 29.568411 | J20: Grade 1 Obesity | K20: 2 | L20: No | M20: No | N20: 27.9 | O20: =IF(N20>18,"Normal","Abnormal") -> Normal | P20: 1 | Q20: 1.1 | R20: =IF(Q20<1,"Abnormal","Normal") -> Normal | S20: 1 | T20: 5.44 | U20: =IF(T20>5.7,"Normal","Abnormal") -> Abnormal | V20: 2 | W20: sarcpenia | X20: 2 | Y20: 2.1 | Z20: =IF(Data!Y20<2.1,"Tertil 1",IF(Data!Y20<=2.6,"Tertil 2","Tertil 3")) -> Tertil 2
B21: 20 | C21: 41 | D21: 2 | E21: female | F21: =IF(E21="Male",1,2) -> 2 | G21: 72.4 | H21: 152 | I21: =SUM(G21/((H21/100)*(H21/100))) -> 31.336565 | J21: Grade 2 Obesity | K21: 3 | L21: No | M21: yes | N21: 21 | O21: =IF(N21>18,"Normal","Abnormal") -> Normal | P21: 1 | Q21: 1 | R21: =IF(Q21<1,"Abnormal","Normal") -> Normal | S21: 1 | T21: 11.98 | U21: =IF(T21>5.7,"Normal","Abnormal") -> Normal | V21: 1 | W21: Normal | X21: 1 | Y21: 4.1 | Z21: =IF(Data!Y21<2.1,"Tertil 1",IF(Data!Y21<=2.6,"Tertil 2","Tertil 3")) -> Tertil 3
B22: 21 | C22: 35 | D22: 1 | E22: female | F22: =IF(E22="Male",1,2) -> 2 | G22: 72 | H22: 150 | I22: =SUM(G22/((H22/100)*(H22/100))) -> 32 | J22: Grade 2 Obesity | K22: 3 | L22: No | M22: No | N22: 20 | O22: =IF(N22>18,"Normal","Abnormal") -> Normal | P22: 1 | Q22: 1.1 | R22: =IF(Q22<1,"Abnormal","Normal") -> Normal | S22: 1 | T22: 4.75 | U22: =IF(T22>5.7,"Normal","Abnormal") -> Abnormal | V22: 2 | W22: sarcpenia | X22: 2 | Y22: 2.5 | Z22: =IF(Data!Y22<2.1,"Tertil 1",IF(Data!Y22<=2.6,"Tertil 2","Tertil 3")) -> Tertil 2
B23: 22 | C23: 31 | D23: 1 | E23: female | F23: =IF(E23="Male",1,2) -> 2 | G23: 70 | H23: 157 | I23: =SUM(G23/((H23/100)*(H23/100))) -> 28.398718 | J23: Grade 1 Obesity | K23: 2 | L23: No | M23: No | N23: 23 | O23: =IF(N23>18,"Normal","Abnormal") -> Normal | P23: 1 | Q23: 1.2 | R23: =IF(Q23<1,"Abnormal","Normal") -> Normal | S23: 1 | T23: 5.2 | U23: =IF(T23>5.7,"Normal","Abnormal") -> Abnormal | V23: 2 | W23: sarcpenia | X23: 2 | Y23: 1.9 | Z23: =IF(Data!Y23<2.1,"Tertil 1",IF(Data!Y23<=2.6,"Tertil 2","Tertil 3")) -> Tertil 1
B24: 23 | C24: 50 | D24: 3 | E24: female | F24: =IF(E24="Male",1,2) -> 2 | G24: 75 | H24: 155 | I24: =SUM(G24/((H24/100)*(H24/100))) -> 31.217482 | J24: Grade 1 Obesity | K24: 2 | L24: No | M24: No | N24: 17.3 | O24: =IF(N24>18,"Normal","Abnormal") -> Abnormal | P24: 2 | Q24: 1 | R24: =IF(Q24<1,"Abnormal","Normal") -> Normal | S24: 1 | T24: 5.26 | U24: =IF(T24>5.7,"Normal","Abnormal") -> Abnormal | V24: 2 | W24: Sarcopenia | X24: 3 | Y24: 1.6 | Z24: =IF(Data!Y24<2.1,"Tertil 1",IF(Data!Y24<=2.6,"Tertil 2","Tertil 3")) -> Tertil 1
B25: 24 | C25: 62 | D25: 4 | E25: female | F25: =IF(E25="Male",1,2) -> 2 | G25: 65 | H25: 155 | I25: =SUM(G25/((H25/100)*(H25/100))) -> 27.055151 | J25: Grade 1 Obesity | K25: 2 | L25: yes | M25: No | N25: 17.3 | O25: =IF(N25>18,"Normal","Abnormal") -> Abnormal | P25: 2 | Q25: 0.9 | R25: =IF(Q25<1,"Abnormal","Normal") -> Abnormal | S25: 2 | T25: 4.64 | U25: =IF(T25>5.7,"Normal","Abnormal") -> Abnormal | V25: 2 | W25: severe sarcopenia | X25: 4 | Y25: 2.1 | Z25: =IF(Data!Y25<2.1,"Tertil 1",IF(Data!Y25<=2.6,"Tertil 2","Tertil 3")) -> Tertil 2
B26: 25 | C26: 40 | D26: 2 | E26: female | F26: =IF(E26="Male",1,2) -> 2 | G26: 83.2 | H26: 150 | I26: =SUM(G26/((H26/100)*(H26/100))) -> 36.977778 | J26: Grade 2 Obesity | K26: 3 | L26: No | M26: No | N26: 16 | O26: =IF(N26>18,"Normal","Abnormal") -> Abnormal | P26: 2 | Q26: 0.8 | R26: =IF(Q26<1,"Abnormal","Normal") -> Abnormal | S26: 2 | T26: 4.7 | U26: =IF(T26>5.7,"Normal","Abnormal") -> Abnormal | V26: 2 | W26: severe sarcopenia | X26: 4 | Y26: 2.6 | Z26: =IF(Data!Y26<2.1,"Tertil 1",IF(Data!Y26<=2.6,"Tertil 2","Tertil 3")) -> Tertil 2
B27: 26 | C27: 41 | D27: 2 | E27: Male | F27: =IF(E27="Male",1,2) -> 1 | G27: 74.7 | H27: 160 | I27: =SUM(G27/((H27/100)*(H27/100))) -> 29.179688 | J27: Grade 1 Obesity | K27: 2 | L27: No | M27: No | N27: 50.9 | O27: =IF(N27>28,"Normal","Abnormal") -> Normal | P27: 1 | Q27: 1.2 | R27: =IF(Q27<1,"Abnormal","Normal") -> Normal | S27: 1 | T27: 9.26 | U27: =IF(T27>7,"Normal","Abnormal") -> Normal | V27: 1 | W27: Normal | X27: 1 | Y27: 1.1 | Z27: =IF(Data!Y27<2.1,"Tertil 1",IF(Data!Y27<=2.6,"Tertil 2","Tertil 3")) -> Tertil 1
B28: 27 | C28: 69 | D28: 4 | E28: Male | F28: =IF(E28="Male",1,2) -> 1 | G28: 70 | H28: 166 | I28: =SUM(G28/((H28/100)*(H28/100))) -> 25.402816 | J28: Grade 1 Obesity | K28: 2 | L28: yes | M28: yes | N28: 29 | O28: =IF(N28>28,"Normal","Abnormal") -> Normal | P28: 1 | Q28: 1 | R28: =IF(Q28<1,"Abnormal","Normal") -> Normal | S28: 1 | T28: 8.5 | U28: =IF(T28>7,"Normal","Abnormal") -> Normal | V28: 1 | W28: Normal | X28: 1 | Y28: 1.5 | Z28: =IF(Data!Y28<2.1,"Tertil 1",IF(Data!Y28<=2.6,"Tertil 2","Tertil 3")) -> Tertil 1
B29: 28 | C29: 62 | D29: 4 | E29: female | F29: =IF(E29="Male",1,2) -> 2 | G29: 70 | H29: 155 | I29: =SUM(G29/((H29/100)*(H29/100))) -> 29.136316 | J29: Grade 1 Obesity | K29: 2 | L29: yes | M29: yes | N29: 20 | O29: =IF(N29>18,"Normal","Abnormal") -> Normal | P29: 1 | Q29: 1 | R29: =IF(Q29<1,"Abnormal","Normal") -> Normal | S29: 1 | T29: 5.5 | U29: =IF(T29>5.7,"Normal","Abnormal") -> Abnormal | V29: 2 | W29: sarcpenia | X29: 2 | Y29: 2 | Z29: =IF(Data!Y29<2.1,"Tertil 1",IF(Data!Y29<=2.6,"Tertil 2","Tertil 3")) -> Tertil 1
B30: 29 | C30: 63 | D30: 4 | E30: female | F30: =IF(E30="Male",1,2) -> 2 | G30: 70 | H30: 150 | I30: =SUM(G30/((H30/100)*(H30/100))) -> 31.111111 | J30: Grade 2 Obesity | K30: 3 | L30: No | M30: yes | N30: 20.7 | O30: =IF(N30>18,"Normal","Abnormal") -> Normal | P30: 1 | Q30: 1 | R30: =IF(Q30<1,"Abnormal","Normal") -> Normal | S30: 1 | T30: 4 | U30: =IF(T30>5.7,"Normal","Abnormal") -> Abnormal | V30: 2 | W30: sarcpenia | X30: 2 | Y30: 2.45 | Z30: =IF(Data!Y30<2.1,"Tertil 1",IF(Data!Y30<=2.6,"Tertil 2","Tertil 3")) -> Tertil 2
B31: 30 | C31: 63 | D31: 4 | E31: Male | F31: =IF(E31="Male",1,2) -> 1 | G31: 76 | H31: 160 | I31: =SUM(G31/((H31/100)*(H31/100))) -> 29.6875 | J31: Grade 1 Obesity | K31: 2 | L31: yes | M31: yes | N31: 19 | O31: =IF(N31>28,"Normal","Abnormal") -> Abnormal | P31: 2 | Q31: 0.8 | R31: =IF(Q31<1,"Abnormal","Normal") -> Abnormal | S31: 2 | T31: 5.5 | U31: =IF(T31>7,"Normal","Abnormal") -> Abnormal | V31: 2 | W31: severe sarcopenia | X31: 4 | Y31: 3 | Z31: =IF(Data!Y31<2.1,"Tertil 1",IF(Data!Y31<=2.6,"Tertil 2","Tertil 3")) -> Tertil 3
B32: 31 | C32: 64 | D32: 4 | E32: female | F32: =IF(E32="Male",1,2) -> 2 | G32: 56 | H32: 154 | I32: =SUM(G32/((H32/100)*(H32/100))) -> 23.612751 | J32: Overweight | K32: 1 | L32: No | M32: yes | N32: 27 | O32: =IF(N32>18,"Normal","Abnormal") -> Normal | P32: 1 | Q32: 1 | R32: =IF(Q32<1,"Abnormal","Normal") -> Normal | S32: 1 | T32: 3 | U32: =IF(T32>5.7,"Normal","Abnormal") -> Abnormal | V32: 2 | W32: sarcpenia | X32: 2 | Y32: 2.2 | Z32: =IF(Data!Y32<2.1,"Tertil 1",IF(Data!Y32<=2.6,"Tertil 2","Tertil 3")) -> Tertil 2
B33: 32 | C33: 67 | D33: 4 | E33: Male | F33: =IF(E33="Male",1,2) -> 1 | G33: 83 | H33: 168 | I33: =SUM(G33/((H33/100)*(H33/100))) -> 29.407596 | J33: Grade 1 Obesity | K33: 2 | L33: No | M33: yes | N33: 30 | O33: =IF(N33>28,"Normal","Abnormal") -> Normal | P33: 1 | Q33: 1 | R33: =IF(Q33<1,"Abnormal","Normal") -> Normal | S33: 1 | T33: 6.2 | U33: =IF(T33>7,"Normal","Abnormal") -> Abnormal | V33: 2 | W33: sarcpenia | X33: 2 | Y33: 2.1 | Z33: =IF(Data!Y33<2.1,"Tertil 1",IF(Data!Y33<=2.6,"Tertil 2","Tertil 3")) -> Tertil 2
B34: 33 | C34: 67 | D34: 4 | E34: female | F34: =IF(E34="Male",1,2) -> 2 | G34: 64 | H34: 145 | I34: =SUM(G34/((H34/100)*(H34/100))) -> 30.439952 | J34: Grade 2 Obesity | K34: 3 | L34: No | M34: No | N34: 22 | O34: =IF(N34>18,"Normal","Abnormal") -> Normal | P34: 1 | Q34: 1 | R34: =IF(Q34<1,"Abnormal","Normal") -> Normal | S34: 1 | T34: 5.8 | U34: =IF(T34>5.7,"Normal","Abnormal") -> Normal | V34: 1 | W34: Normal | X34: 1 | Y34: 1.7 | Z34: =IF(Data!Y34<2.1,"Tertil 1",IF(Data!Y34<=2.6,"Tertil 2","Tertil 3")) -> Tertil 1
B35: 34 | C35: 64 | D35: 4 | E35: female | F35: =IF(E35="Male",1,2) -> 2 | G35: 55 | H35: 145 | I35: =SUM(G35/((H35/100)*(H35/100))) -> 26.159334 | J35: Grade 1 Obesity | K35: 2 | L35: No | M35: yes | N35: 11.8 | O35: =IF(N35>18,"Normal","Abnormal") -> Abnormal | P35: 2 | Q35: 1 | R35: =IF(Q35<1,"Abnormal","Normal") -> Normal | S35: 1 | T35: 5.1 | U35: =IF(T35>5.7,"Normal","Abnormal") -> Abnormal | V35: 2 | W35: Sarcopenia | X35: 3 | Y35: 2.5 | Z35: =IF(Data!Y35<2.1,"Tertil 1",IF(Data!Y35<=2.6,"Tertil 2","Tertil 3")) -> Tertil 2
B36: 35 | C36: 67 | D36: 4 | E36: Male | F36: =IF(E36="Male",1,2) -> 1 | G36: 60 | H36: 153 | I36: =SUM(G36/((H36/100)*(H36/100))) -> 25.631167 | J36: Grade 1 Obesity | K36: 2 | L36: No | M36: yes | N36: 18 | O36: =IF(N36>28,"Normal","Abnormal") -> Abnormal | P36: 2 | Q36: 1.2 | R36: =IF(Q36<1,"Abnormal","Normal") -> Normal | S36: 1 | T36: 7.1 | U36: =IF(T36>7,"Normal","Abnormal") -> Normal | V36: 1 | W36: sarcpenia | X36: 2 | Y36: 2 | Z36: =IF(Data!Y36<2.1,"Tertil 1",IF(Data!Y36<=2.6,"Tertil 2","Tertil 3")) -> Tertil 1
B37: 36 | C37: 70 | D37: 4 | E37: Male | F37: =IF(E37="Male",1,2) -> 1 | G37: 73 | H37: 168 | I37: =SUM(G37/((H37/100)*(H37/100))) -> 25.864512 | J37: Grade 1 Obesity | K37: 2 | L37: No | M37: yes | N37: 22 | O37: =IF(N37>28,"Normal","Abnormal") -> Abnormal | P37: 2 | Q37: 1 | R37: =IF(Q37<1,"Abnormal","Normal") -> Normal | S37: 1 | T37: 6.3 | U37: =IF(T37>7,"Normal","Abnormal") -> Abnormal | V37: 2 | W37: Sarcopenia | X37: 3 | Y37: 2.1 | Z37: =IF(Data!Y37<2.1,"Tertil 1",IF(Data!Y37<=2.6,"Tertil 2","Tertil 3")) -> Tertil 2
B38: 37 | C38: 68 | D38: 4 | E38: Male | F38: =IF(E38="Male",1,2) -> 1 | G38: 79 | H38: 162 | I38: =SUM(G38/((H38/100)*(H38/100))) -> 30.102119 | J38: Grade 2 Obesity | K38: 3 | L38: No | M38: yes | N38: 28 | O38: =IF(N38>28,"Normal","Abnormal") -> Abnormal | P38: 2 | Q38: 0.9 | R38: =IF(Q38<1,"Abnormal","Normal") -> Abnormal | S38: 2 | T38: 7.3 | U38: =IF(T38>7,"Normal","Abnormal") -> Normal | V38: 1 | W38: Sarcopenia | X38: 3 | Y38: 1.8 | Z38: =IF(Data!Y38<2.1,"Tertil 1",IF(Data!Y38<=2.6,"Tertil 2","Tertil 3")) -> Tertil 1
B39: 38 | C39: 73 | D39: 4 | E39: female | F39: =IF(E39="Male",1,2) -> 2 | G39: 55 | H39: 150 | I39: =SUM(G39/((H39/100)*(H39/100))) -> 24.444444 | J39: Overweight | K39: 1 | L39: No | M39: No | N39: 14.8 | O39: =IF(N39>18,"Normal","Abnormal") -> Abnormal | P39: 2 | Q39: 0.7 | R39: =IF(Q39<1,"Abnormal","Normal") -> Abnormal | S39: 2 | T39: 5.8 | U39: =IF(T39>5.7,"Normal","Abnormal") -> Normal | V39: 1 | W39: Sarcopenia | X39: 3 | Y39: 2 | Z39: =IF(Data!Y39<2.1,"Tertil 1",IF(Data!Y39<=2.6,"Tertil 2","Tertil 3")) -> Tertil 1
B40: 39 | C40: 67 | D40: 4 | E40: female | F40: =IF(E40="Male",1,2) -> 2 | G40: 62 | H40: 150 | I40: =SUM(G40/((H40/100)*(H40/100))) -> 27.555556 | J40: Grade 1 Obesity | K40: 2 | L40: No | M40: No | N40: 32 | O40: =IF(N40>18,"Normal","Abnormal") -> Normal | P40: 1 | Q40: 1 | R40: =IF(Q40<1,"Abnormal","Normal") -> Normal | S40: 1 | T40: 6 | U40: =IF(T40>5.7,"Normal","Abnormal") -> Normal | V40: 1 | W40: Normal | X40: 1 | Y40: 1.3 | Z40: =IF(Data!Y40<2.1,"Tertil 1",IF(Data!Y40<=2.6,"Tertil 2","Tertil 3")) -> Tertil 1
...

Sheet Description
A2: Suhardi FL, Aman AM, Sudarso A et al. HOMA-IR Values in Overweight and Obesity Subjects With and Without Sarcopenia. F1000Research 2026, 15:313 (https://doi.org/10.12688/f1000research.177884.1)
A4: Data availability: https://doi.org/10.5281/zenodo.18478899
A6: Variable | B6: Name
A7: No | B7: ID
A8: Age | B8: Age
A9: Age Category | B9: Age group
A10: Gender | B10: Sex
A11: GenderCategory | B11: Sex category
A12: Body weight | B12: Weight
A13: body height | B13: Height
A14: BMI | B14: BMI
A15: Obesity category | B15: Obesity class
A16: BMI category | B16: BMI category
A17: Hypertension | B17: Hypertension
... A31: Tertil HOMA-IR | B31: HOMA-IR tertile
